Workbook

Sheet README
A1: PreCAS question bank — harvested 17 August 2026
A3: What this is | B3: Every pre-CAS / UKVI credibility interview question found by fetching 33 live web pages.
B4: Nothing here was invented. Each row carries the page it came from.
A6: Raw questions captured | B6: 534
A7: Unique question concepts after dedupe | B7: 401
A8: Backed by a university (.ac.uk) page | B8: 226
A9: Corroborated by 2 or more sources | B9: 67
A10: Corroborated by 3 or more sources | B10: 34
A11: Distinct source pages fetched | B11: 33
A13: Current bank in the product | B13: 26
A14: Questions per full mock | B14: 17
A16: How to use this sheet | B16: Work down the QUESTIONS tab. Set the Keep column to Y or N.
B17: Sort by Sources descending — the most-corroborated questions are the ones real interviews actually ask.
B18: Anything with 2+ sources and a .ac.uk tier is safe to ship without further checking.
A20: Important | B20: The question is the SAME for every university. What changes is the correct ANSWER.
B21: That is why there is no "university" column here. See the architecture note that came with this file.

Sheet QUESTIONS
A1: # | B1: Topic | C1: Question | D1: Sources | E1: Tiers | F1: Keep (Y/N) | G1: Source 1 | H1: URL 1 | I1: Source 2 | J1: URL 2 | K1: Other wordings seen
A2: 1 | B2: 3. Why this course | C2: Why did you choose this course? | D2: 9 | E2: agent, primary | G2: Birmingham City University — Credibility interviews | H2: https://www.bcu.ac.uk/international/preparing-for-the-uk/getting-your-visa/credibility-interviews | I2: Meridean Overseas Education Consultants — Pre-CAS Interview Preparation | J2: https://www.meridean.org/blog/pre-cas-interview | K2: Why did you choose your course?
A3: 2 | B3: 1. Why the UK | C3: Why do you want to study at University of Kent? | D3: 8 | E3: agent, primary | G3: Meridean Overseas Education Consultants — Pre-CAS Interview Preparation | H3: https://www.meridean.org/blog/pre-cas-interview | I3: Middlesex University — Preparing for your credibility interview | J3: https://www.mdx.ac.uk/international/student-visas/your-interview/ | K3: Why do you want to study in the UK?
A4: 3 | B4: 1. Why the UK | C4: Why have you chosen your course of study? | D4: 6 | E4: agent, primary | G4: NWC Education (Nepal) — Pre-CAS Interview Guide for Nepali Students | H4: https://nwc.education/pre-cas-interview-questions-preparation-for-nepali/ | I4: Northumbria University — Credibility interviews | J4: https://www.northumbria.ac.uk/study-at-northumbria/immigration/credibility-interviews/ | K4: What course have you chosen and why? | Why have you chosen this course? | Why have you chosen to study in the UK?
A5: 4 | B5: 3. Why this course | C5: How will your course be taught and assessed? | D5: 5 | E5: primary | G5: Coventry University — Credibility interviews | H5: https://www.coventry.ac.uk/international-students-hub/coming-to-the-uk/your-visa/credibility-interviews/ | I5: SOAS University of London — Credibility Interviews: Student Visa Applications | J5: https://www.soas.ac.uk/sites/default/files/2022-10/Credibility%20Interviews-%20student%20visa%20applications_0.pdf | K5: How is your course assessed?
A6: 5 | B6: 2. Why this university | C6: Which other colleges / universities have you considered? | D6: 5 | E6: agent, primary | G6: SOAS University of London — Credibility Interviews: Student Visa Applications | H6: https://www.soas.ac.uk/sites/default/files/2022-10/Credibility%20Interviews-%20student%20visa%20applications_0.pdf | I6: Sheffield Hallam University — Credibility interview practice questions (PDF) | J6: https://www.shu.ac.uk/-/media/home/international/files/int-credibility-interview-practice-qs.pdf | K6: Have you considered other colleges/Universities? | What other universities have you considered in the UK? | Which other colleges/universities have you considered?
A7: 6 | B7: 8. Accommodation & living | C7: How much will your accommodation cost? | D7: 4 | E7: primary | G7: Middlesex University — Preparing for your credibility interview | H7: https://www.mdx.ac.uk/international/student-visas/your-interview/ | I7: Oxford Brookes University — UKVI Credibility interviews | J7: https://www.brookes.ac.uk/students/isat/visas/student-visa/credibility-interviews
A8: 7 | B8: 6. Education history | C8: Why have you chosen this course and how does it relate to your previous study? | D8: 4 | E8: agent, primary | G8: Sheffield Hallam University — Credibility interview practice questions (PDF) | H8: https://www.shu.ac.uk/-/media/home/international/files/int-credibility-interview-practice-qs.pdf | I8: Staffordshire University — Guide to Credibility Interviews (PDF) | J8: https://www.staffs.ac.uk/international/pdf/guide-to-credibility-interviews.pdf | K8: Why did you choose this course and how does it relate to your previous study?
A9: 8 | B9: 6. Education history | C9: You have previously studied in the UK - why have you chosen to return? | D9: 4 | E9: agent, primary | G9: Birmingham City University — Credibility interviews | H9: https://www.bcu.ac.uk/international/preparing-for-the-uk/getting-your-visa/credibility-interviews | I9: Road To Abroad — Credibility Interview for UK: Sample Questions and Answers | J9: https://roadtoabroad.co.in/credibility-interview-for-uk/ | K9: You have previously studied in the UK – why have you chosen to return?
A10: 9 | B10: 4. Finance | C10: How will you fund your studies? | D10: 4 | E10: agent, primary | G10: Birmingham City University — Credibility interviews | H10: https://www.bcu.ac.uk/international/preparing-for-the-uk/getting-your-visa/credibility-interviews | I10: Road To Abroad — Credibility Interview for UK: Sample Questions and Answers | J10: https://roadtoabroad.co.in/credibility-interview-for-uk/
A11: 10 | B11: 5. Post-study plans | C11: How do your studies fit in with your career plans? | D11: 4 | E11: agent, primary | G11: Birmingham City University — Credibility interviews | H11: https://www.bcu.ac.uk/international/preparing-for-the-uk/getting-your-visa/credibility-interviews | I11: Road To Abroad — Credibility Interview for UK: Sample Questions and Answers | J11: https://roadtoabroad.co.in/credibility-interview-for-uk/ | K11: How do your studies fit into your career plans?
A12: 11 | B12: 7. Study gap | C12: You have had a (long) break in your studies, why are you returning to study now? | D12: 4 | E12: agent, primary | G12: Birmingham City University — Credibility interviews | H12: https://www.bcu.ac.uk/international/preparing-for-the-uk/getting-your-visa/credibility-interviews | I12: Road To Abroad — Credibility Interview for UK: Sample Questions and Answers | J12: https://roadtoabroad.co.in/credibility-interview-for-uk/ | K12: You have had a long break from your studies. Why are you returning to study now? | You have had a long break in your studies, why are you returning to study now?
A13: 12 | B13: 3. Why this course | C13: What modules will you study? | D13: 4 | E13: agent, primary | G13: Edwise Foundation (Nepal) — Pre-CAS Interview for Nepali Students | H13: https://edwisefoundation.com/pre-cas-interview-nepali-students/ | I13: Middlesex University — Preparing for your credibility interview | J13: https://www.mdx.ac.uk/international/student-visas/your-interview/
A14: 13 | B14: 3. Why this course | C14: How long does your course last? | D14: 4 | E14: agent, primary | G14: Middlesex University — Preparing for your credibility interview | H14: https://www.mdx.ac.uk/international/student-visas/your-interview/ | I14: Staffordshire University — Guide to Credibility Interviews (PDF) | J14: https://www.staffs.ac.uk/international/pdf/guide-to-credibility-interviews.pdf | K14: How long is the course? | How long is your course?
A15: 14 | B15: 3. Why this course | C15: What qualification will you receive when you graduate? | D15: 4 | E15: agent, primary | G15: Middlesex University — Preparing for your credibility interview | H15: https://www.mdx.ac.uk/international/student-visas/your-interview/ | I15: Staffordshire University — Guide to Credibility Interviews (PDF) | J15: https://www.staffs.ac.uk/international/pdf/guide-to-credibility-interviews.pdf | K15: What qualification will you receive?
A16: 15 | B16: 8. Accommodation & living | C16: Where will you live in the UK? | D16: 3 | E16: agent, primary | G16: Birmingham City University — Credibility interviews | H16: https://www.bcu.ac.uk/international/preparing-for-the-uk/getting-your-visa/credibility-interviews | I16: Edwise Foundation (Nepal) — Pre-CAS Interview for Nepali Students | J16: https://edwisefoundation.com/pre-cas-interview-nepali-students/ | K16: Where will you live?
A17: 16 | B17: 4. Finance | C17: Who will be financing the costs of your studies? | D17: 3 | E17: agent, primary | G17: Northumbria University — Credibility interviews | H17: https://www.northumbria.ac.uk/study-at-northumbria/immigration/credibility-interviews/ | I17: SOAS University of London — Credibility Interviews: Student Visa Applications | J17: https://www.soas.ac.uk/sites/default/files/2022-10/Credibility%20Interviews-%20student%20visa%20applications_0.pdf | K17: How are you financing your studies? | Who is financing your studies?
A18: 17 | B18: 4. Finance | C18: Do you know how you will you pay for your studies and living costs? | D18: 3 | E18: primary | G18: Middlesex University — Preparing for your credibility interview | H18: https://www.mdx.ac.uk/international/student-visas/your-interview/ | I18: University of Aberdeen — Credibility Interview | J18: https://www.abdn.ac.uk/study/international/credibility-interview-2559.php | K18: How will you pay for your studies and living costs? | How will you pay for your studies/living costs?
A19: 18 | B19: 4. Finance | C19: How are you funding your studies? | D19: 3 | E19: agent, primary | G19: Sheffield Hallam University — Credibility interview practice questions (PDF) | H19: https://www.shu.ac.uk/-/media/home/international/files/int-credibility-interview-practice-qs.pdf | I19: University of Aberdeen — Credibility Interview | J19: https://www.abdn.ac.uk/study/international/credibility-interview-2559.php | K19: Who is funding your studies?
A20: 19 | B20: 4. Finance | C20: If the costs of pursuing your course of study are higher in the UK than in your home country, why have you decided to incur the extra costs involved with studying in the UK? | D20: 3 | E20: agent, primary | G20: Road To Abroad — Credibility Interview for UK: Sample Questions and Answers | H20: https://roadtoabroad.co.in/credibility-interview-for-uk/ | I20: SOAS University of London — Credibility Interviews: Student Visa Applications | J20: https://www.soas.ac.uk/sites/default/files/2022-10/Credibility%20Interviews-%20student%20visa%20applications_0.pdf | K20: The costs of pursuing your course of study are higher in the UK than in your home country, why have you decided to incur the extra costs by studying in the UK?
A21: 20 | B21: 4. Finance | C21: What are your parents' annual income? | D21: 3 | E21: agent, primary | G21: Leverage Edu Learn — Pre-CAS Interview Prep: Commonly Asked Questions | H21: https://leverageedu.com/learn/visa-pre-cas-interview/ | I21: University of Reading — UKVI interview information for prospective students | J21: https://www.reading.ac.uk/essentials/International/Visa-and-immigration/credibility-interviews | K21: What is the annual income of your parents? | What is your parents' annual income?
A22: 21 | B22: 5. Post-study plans | C22: What are your future plans? | D22: 3 | E22: agent, primary | G22: Meridean Overseas Education Consultants — Pre-CAS Interview Preparation | H22: https://www.meridean.org/blog/pre-cas-interview | I22: University of Aberdeen — Credibility Interview | J22: https://www.abdn.ac.uk/study/international/credibility-interview-2559.php | K22: What are your future career plans?
A23: 22 | B23: 5. Post-study plans | C23: What is the relevance of the course to your future career path? | D23: 3 | E23: agent, primary | G23: Sheffield Hallam University — Credibility interview practice questions (PDF) | H23: https://www.shu.ac.uk/-/media/home/international/files/int-credibility-interview-practice-qs.pdf | I23: Staffordshire University — Guide to Credibility Interviews (PDF) | J23: https://www.staffs.ac.uk/international/pdf/guide-to-credibility-interviews.pdf
A24: 23 | B24: 5. Post-study plans | C24: Are you planning to stay in the UK on completion of your course to study for a higher award? | D24: 3 | E24: agent, primary | G24: Sheffield Hallam University — Credibility interview practice questions (PDF) | H24: https://www.shu.ac.uk/-/media/home/international/files/int-credibility-interview-practice-qs.pdf | I24: Staffordshire University — Guide to Credibility Interviews (PDF) | J24: https://www.staffs.ac.uk/international/pdf/guide-to-credibility-interviews.pdf | K24: After your course, are you planning to stay in the UK to study for a higher award? | Are you planning to stay in the UK on completion to study for a higher award?
A25: 24 | B25: 9. Visa & compliance | C25: Have you had any visa refusals in the past? | D25: 3 | E25: agent, primary | G25: Leverage Edu Learn — Pre-CAS Interview Prep: Commonly Asked Questions | H25: https://leverageedu.com/learn/visa-pre-cas-interview/ | I25: Meridean Overseas Education Consultants — Pre-CAS Interview Preparation | J25: https://www.meridean.org/blog/pre-cas-interview | K25: Do you have any past visa refusals? | Have you had any visa refusals?
A26: 25 | B26: 9. Visa & compliance | C26: Are you thinking of transferring to another institution on completion of your course? | D26: 3 | E26: agent, primary | G26: Sheffield Hallam University — Credibility interview practice questions (PDF) | H26: https://www.shu.ac.uk/-/media/home/international/files/int-credibility-interview-practice-qs.pdf | I26: Staffordshire University — Guide to Credibility Interviews (PDF) | J26: https://www.staffs.ac.uk/international/pdf/guide-to-credibility-interviews.pdf | K26: After your course, are you thinking of transferring to another institution? | Are you thinking of transferring to another institution on completing this course?
A27: 26 | B27: 7. Study gap | C27: Can you explain the gaps in your study/professional history? | D27: 3 | E27: agent, primary | G27: Sheffield Hallam University — Credibility interview practice questions (PDF) | H27: https://www.shu.ac.uk/-/media/home/international/files/int-credibility-interview-practice-qs.pdf | I27: Staffordshire University — Guide to Credibility Interviews (PDF) | J27: https://www.staffs.ac.uk/international/pdf/guide-to-credibility-interviews.pdf | K27: How do you explain the gaps in your study history? | How do you explain the gaps in your study/professional history?
A28: 27 | B28: 3. Why this course | C28: What other courses (if any) did you consider studying? | D28: 3 | E28: primary | G28: Middlesex University — Preparing for your credibility interview | H28: https://www.mdx.ac.uk/international/student-visas/your-interview/ | I28: University of Aberdeen — Credibility Interview | J28: https://www.abdn.ac.uk/study/international/credibility-interview-2559.php | K28: What other courses did you consider?
A29: 28 | B29: 3. Why this course | C29: How is your chosen course assessed? | D29: 3 | E29: agent, primary | G29: Sheffield Hallam University — Credibility interview practice questions (PDF) | H29: https://www.shu.ac.uk/-/media/home/international/files/int-credibility-interview-practice-qs.pdf | I29: Staffordshire University — Guide to Credibility Interviews (PDF) | J29: https://www.staffs.ac.uk/international/pdf/guide-to-credibility-interviews.pdf
A30: 29 | B30: 3. Why this course | C30: Does this course offer any professional recognition? | D30: 3 | E30: agent, primary | G30: Sheffield Hallam University — Credibility interview practice questions (PDF) | H30: https://www.shu.ac.uk/-/media/home/international/files/int-credibility-interview-practice-qs.pdf | I30: Staffordshire University — Guide to Credibility Interviews (PDF) | J30: https://www.staffs.ac.uk/international/pdf/guide-to-credibility-interviews.pdf
A31: 30 | B31: 1. Why the UK | C31: What are the benefits of studying in the UK compared to your home country or other countries that mean it is worth the cost to you? | D31: 3 | E31: primary | G31: Oxford Brookes University — UKVI Credibility interviews | H31: https://www.brookes.ac.uk/students/isat/visas/student-visa/credibility-interviews | I31: SOAS University of London — Credibility Interviews: Student Visa Applications | J31: https://www.soas.ac.uk/sites/default/files/2022-10/Credibility%20Interviews-%20student%20visa%20applications_0.pdf | K31: What are the benefits of studying in the UK compared to your home country or any other countries? | What are the benefits of studying in the UK compared to your home country?
A32: 31 | B32: 2. Why this university | C32: What other universities did you consider? Why? | D32: 3 | E32: primary | G32: Coventry University — Credibility interviews | H32: https://www.coventry.ac.uk/international-students-hub/coming-to-the-uk/your-visa/credibility-interviews/ | I32: University of Bradford — Credibility checks: Student visas | J32: https://www.bradford.ac.uk/international/support/visa-support/student-visas/credibility-checks/ | K32: Which other Universities did you consider? | Which other universities did you consider?
A33: 32 | B33: 2. Why this university | C33: How did you find out about it? | D33: 3 | E33: agent, primary | G33: Sheffield Hallam University — Credibility interview practice questions (PDF) | H33: https://www.shu.ac.uk/-/media/home/international/files/int-credibility-interview-practice-qs.pdf | I33: Staffordshire University — Guide to Credibility Interviews (PDF) | J33: https://www.staffs.ac.uk/international/pdf/guide-to-credibility-interviews.pdf
A34: 33 | B34: 2. Why this university | C34: Do you know anyone else who has already studied there? | D34: 3 | E34: agent, primary | G34: Sheffield Hallam University — Credibility interview practice questions (PDF) | H34: https://www.shu.ac.uk/-/media/home/international/files/int-credibility-interview-practice-qs.pdf | I34: Staffordshire University — Guide to Credibility Interviews (PDF) | J34: https://www.staffs.ac.uk/international/pdf/guide-to-credibility-interviews.pdf | K34: Do you know anyone who has already studied there?
A35: 34 | B35: 2. Why this university | C35: Why did you choose Birmingham City University (BCU)? | D35: 3 | E35: agent, primary | G35: Birmingham City University — Credibility interviews | H35: https://www.bcu.ac.uk/international/preparing-for-the-uk/getting-your-visa/credibility-interviews | I35: Meridean Overseas Education Consultants — Pre-CAS Interview Preparation | J35: https://www.meridean.org/blog/pre-cas-interview | K35: Why did you choose Roehampton University? | Why did you choose this university?
A36: 35 | B36: 8. Accommodation & living | C36: Where do you plan to live during your studies at Northumbria University? | D36: 2 | E36: primary | G36: Northumbria University — Credibility interviews | H36: https://www.northumbria.ac.uk/study-at-northumbria/immigration/credibility-interviews/ | I36: Oxford Brookes University — UKVI Credibility interviews | J36: https://www.brookes.ac.uk/students/isat/visas/student-visa/credibility-interviews | K36: Where do you plan to live during your studies?
A37: 36 | B37: 6. Education history | C37: Have you studied abroad previously? | D37: 2 | E37: primary | G37: University of Hertfordshire — Sponsorship interview | H37: https://www.herts.ac.uk/international/apply/offer-holder-guidance/sponsorship-interview | I37: University of Lincoln — Pre-CAS Interview | Information for Offer Holders | J37: https://www.lincoln.ac.uk/studywithus/internationalstudents/informationforofferholders/pre-casinterview/ | K37: What have you studied previously?
A38: 37 | B38: 4. Finance | C38: How much are the tuition fees? | D38: 2 | E38: primary | G38: Middlesex University — Preparing for your credibility interview | H38: https://www.mdx.ac.uk/international/student-visas/your-interview/ | I38: University of Aberdeen — Credibility Interview | J38: https://www.abdn.ac.uk/study/international/credibility-interview-2559.php
A39: 38 | B39: 4. Finance | C39: Are you able to pay your tuition fees in full up front? | D39: 2 | E39: agent, primary | G39: SOAS University of London — Credibility Interviews: Student Visa Applications | H39: https://www.soas.ac.uk/sites/default/files/2022-10/Credibility%20Interviews-%20student%20visa%20applications_0.pdf | I39: Staffordshire University — Guide to Credibility Interviews (PDF) | J39: https://www.staffs.ac.uk/international/pdf/guide-to-credibility-interviews.pdf | K39: Would you be able to pay your tuition fees in full up front?
A40: 39 | B40: 4. Finance | C40: Have you checked the University refund policy? | D40: 2 | E40: agent, primary | G40: SOAS University of London — Credibility Interviews: Student Visa Applications | H40: https://www.soas.ac.uk/sites/default/files/2022-10/Credibility%20Interviews-%20student%20visa%20applications_0.pdf | I40: Staffordshire University — Guide to Credibility Interviews (PDF) | J40: https://www.staffs.ac.uk/international/pdf/guide-to-credibility-interviews.pdf | K40: Have you checked the refund policy?
...

Sheet BY TOPIC
A1: Topic | B1: Questions found | C1: Questions per mock (target) | D1: Have enough?
A2: 1. Why the UK | B2: =COUNTIF(QUESTIONS!$B$2:$B$402,A2) -> 30 | C2: 2 | D2: =IF(B2>=C2*8,"yes","needs more") -> yes
A3: 10. Identity & personal | B3: =COUNTIF(QUESTIONS!$B$2:$B$402,A3) -> 11 | C3: 1 | D3: =IF(B3>=C3*8,"yes","needs more") -> yes
A4: 11. English ability | B4: =COUNTIF(QUESTIONS!$B$2:$B$402,A4) -> 4 | C4: 1 | D4: =IF(B4>=C4*8,"yes","needs more") -> needs more
A5: 12. Other | B5: =COUNTIF(QUESTIONS!$B$2:$B$402,A5) -> 5 | C5: 0 | D5: =IF(B5>=C5*8,"yes","needs more") -> yes
A6: 2. Why this university | B6: =COUNTIF(QUESTIONS!$B$2:$B$402,A6) -> 54 | C6: 3 | D6: =IF(B6>=C6*8,"yes","needs more") -> yes
A7: 3. Why this course | B7: =COUNTIF(QUESTIONS!$B$2:$B$402,A7) -> 48 | C7: 3 | D7: =IF(B7>=C7*8,"yes","needs more") -> yes
A8: 4. Finance | B8: =COUNTIF(QUESTIONS!$B$2:$B$402,A8) -> 82 | C8: 3 | D8: =IF(B8>=C8*8,"yes","needs more") -> yes
A9: 5. Post-study plans | B9: =COUNTIF(QUESTIONS!$B$2:$B$402,A9) -> 44 | C9: 2 | D9: =IF(B9>=C9*8,"yes","needs more") -> yes
A10: 6. Education history | B10: =COUNTIF(QUESTIONS!$B$2:$B$402,A10) -> 21 | C10: 1 | D10: =IF(B10>=C10*8,"yes","needs more") -> yes
A11: 7. Study gap | B11: =COUNTIF(QUESTIONS!$B$2:$B$402,A11) -> 17 | C11: 1 | D11: =IF(B11>=C11*8,"yes","needs more") -> yes
A12: 8. Accommodation & living | B12: =COUNTIF(QUESTIONS!$B$2:$B$402,A12) -> 37 | C12: 1 | D12: =IF(B12>=C12*8,"yes","needs more") -> yes
A13: 9. Visa & compliance | B13: =COUNTIF(QUESTIONS!$B$2:$B$402,A13) -> 48 | C13: 1 | D13: =IF(B13>=C13*8,"yes","needs more") -> yes
A14: TOTAL | B14: =SUM(B2:B13) -> 401 | C14: =SUM(C2:C13) -> 19
A16: Rule of thumb: a student should not meet a repeat before mock 3.
A17: So each topic needs about 8x the number of slots it fills in one mock.

Sheet SOURCES
A1: Source page | B1: URL | C1: Tier | D1: Questions from it
A2: The Mentors Circle — UK Student Visa Interview Questions 2026: India Guide | B2: https://thementorscircle.com/blogs/post/uk-student-visa-interview-questions-2026-indian-students-guide/ | C2: agent | D2: 48
A3: Staffordshire University — Guide to Credibility Interviews (PDF) | B3: https://www.staffs.ac.uk/international/pdf/guide-to-credibility-interviews.pdf | C3: agent | D3: 42
A4: University of Aberdeen — Credibility Interview | B4: https://www.abdn.ac.uk/study/international/credibility-interview-2559.php | C4: primary | D4: 36
A5: University of Reading — UKVI interview information for prospective students | B5: https://www.reading.ac.uk/essentials/International/Visa-and-immigration/credibility-interviews | C5: primary | D5: 32
A6: Oxford Brookes University — UKVI Credibility interviews | B6: https://www.brookes.ac.uk/students/isat/visas/student-visa/credibility-interviews | C6: primary | D6: 28
A7: Sheffield Hallam University — Credibility interview practice questions (PDF) | B7: https://www.shu.ac.uk/-/media/home/international/files/int-credibility-interview-practice-qs.pdf | C7: primary | D7: 28
A8: NWC Education (Nepal) — Pre-CAS Interview Guide for Nepali Students | B8: https://nwc.education/pre-cas-interview-questions-preparation-for-nepali/ | C8: agent | D8: 27
A9: SOAS University of London — Credibility Interviews: Student Visa Applications | B9: https://www.soas.ac.uk/sites/default/files/2022-10/Credibility%20Interviews-%20student%20visa%20applications_0.pdf | C9: primary | D9: 23
A10: University of Bradford — Credibility checks: Student visas | B10: https://www.bradford.ac.uk/international/support/visa-support/student-visas/credibility-checks/ | C10: primary | D10: 21
A11: University of Westminster — Credibility interviews | B11: https://www.westminster.ac.uk/international/visas-and-advice/visas/student-visa/credibility-interviews | C11: primary | D11: 20
A12: Bournemouth University — Credibility interviews: information for international applicants | B12: https://www.bournemouth.ac.uk/students/help-advice/international-students/immigration-visas/student-route-visa/visa-application-credibility-interviews | C12: primary | D12: 19
A13: Middlesex University — Preparing for your credibility interview | B13: https://www.mdx.ac.uk/international/student-visas/your-interview/ | C13: primary | D13: 18
... A34: Rajveer Chahal — UKVI Credibility Interview Questions & Answers 2026 | B34: https://rajveerchahal.com/ukvi-credibility-interview-questions-answers-2026/ | C34: agent | D34: 2
